Workbook
Name IQ_CH: 110000
Name IQ_CQ: 5000
Name IQ_CY: 10000
Name IQ_DAILY: 500000
Name IQ_FH: 100000
Name IQ_FQ: 500
Name IQ_FY: 1000
Name IQ_LTM: 2000
Name IQ_MONTH: 15000
Name IQ_NTM: 6000
Name IQ_WEEK: 50000
Name IQ_YTD: 3000
Name UPDATE: 'Data Sheet'!$E$1

Sheet Data>

Sheet Data Room>

Sheet Football Field Analysis
L4: Fooball Field Analysis - Data
N5: Open Low | O5: Low | P5: Open High | Q5: High
L6: Relative Valuation | N6: 1393.8 | O6: =N6 -> 1393.8 | P6: 1797.1 | Q6: =P6 -> 1797.1
L7: DCF Bear | N7: ='DCF>'!J17 -> 468.20006 | O7: =N7 -> 468.20006 | P7: ='DCF>'!J22 -> 665.9116 | Q7: =P7 -> 665.9116
L8: DCF Base | N8: ='DCF>'!H17 -> 514.97547 | O8: =N8 -> 514.97547 | P8: ='DCF>'!H22 -> 791.08837 | Q8: =P8 -> 791.08837
L9: DCF Bull | N9: ='DCF>'!G17 -> 545.08788 | O9: =N9 -> 545.08788 | P9: 883.4 | Q9: =P9 -> 883.4
L10: 52 Weeks Range | N10: 2115 | O10: =N10 -> 2115 | P10: 2985.7 | Q10: =P10 -> 2985.7

Sheet VAR
B1: 5 Year -Daily
B3: Date | C3: Price | D3: Returns | E3: Shorted Returns | G3: Replication | H3: Simulated Returns | J3: calculation of value at Risk -Asian Paints (Historical)
B4: 43910 | C4: 1741.2 | D4: =(C4-C5)/C5 -> -0.37399558 | E4: 0.094096579 | G4: 1 | H4: =_xlfn.NORM.INV(RAND(),N$6,N$7) -> -0.015343303
B5: 44330 | C5: 2781.45 | D5: =(C5-C6)/C6 -> 0.65779592 | E5: 0.086503906 | G5: 2 | H5: =_xlfn.NORM.INV(RAND(),N$6,N$7) -> 0.0075337319 | J5: Historical Approach
B6: 43728 | C6: 1677.8 | D6: =(C6-C7)/C7 -> 0.024204133 | E6: 0.080221478 | G6: 3 | H6: =_xlfn.NORM.INV(RAND(),N$6,N$7) -> -0.0064417568 | J6: Mean | N6: =AVERAGE(E4:E2746) -> 0.00058458404
B7: 43928 | C7: 1638.15 | D7: =(C7-C8)/C8 -> -0.089208273 | E7: 0.075501428 | G7: 4 | H7: =_xlfn.NORM.INV(RAND(),N$6,N$7) -> -0.00020652813 | J7: Std | N7: =_xlfn.STDEV.S(E4:E2746) -> 0.015235186
B8: 43731 | C8: 1798.6 | D8: =(C8-C9)/C9 -> 0.39534523 | E8: 0.071999046 | G8: 5 | H8: =_xlfn.NORM.INV(RAND(),N$6,N$7) -> 0.0041436042 | J8: Min | N8: =MIN(E4:E2746) -> -0.14323455
B9: 43231 | C9: 1289 | D9: =(C9-C10)/C10 -> -0.3101049 | E9: 0.062391824 | G9: 6 | H9: =_xlfn.NORM.INV(RAND(),N$6,N$7) -> 0.014883259 | J9: Max | N9: =MAX(E4:E2746) -> 0.094096579
B10: 43864 | C10: 1868.4 | D10: =(C10-C11)/C11 -> -0.41030173 | E10: 0.060686915 | G10: 7 | H10: =_xlfn.NORM.INV(RAND(),N$6,N$7) -> -0.0098921144 | J10: current Price | N10: ='Data Sheet'!B8 -> 2605.6
B11: 44397 | C11: 3168.4 | D11: =(C11-C12)/C12 -> 1.8116071 | E11: 0.060481307 | G11: 8 | H11: =_xlfn.NORM.INV(RAND(),N$6,N$7) -> -0.021209391
B12: 42579 | C12: 1126.9 | D12: =(C12-C13)/C13 -> -0.60840935 | E12: 0.059315661 | G12: 9 | H12: =_xlfn.NORM.INV(RAND(),N$6,N$7) -> -0.005164497 | J12: Percentile | K12: Confidence | L12: VAR% | M12: Stock Price | N12: VAR(INR)
B13: 44629 | C13: 2877.75 | D13: =(C13-C14)/C14 -> 0.31320161 | E13: 0.053850661 | G13: 10 | H13: =_xlfn.NORM.INV(RAND(),N$6,N$7) -> -0.0037913592 | J13: 0.05 | K13: =100%-J13 -> 0.95 | L13: =_xlfn.PERCENTILE.INC($E$4:$E$2746,J13) -> -0.022436073 | M13: =$N$10*(1-L13) -> 2664.0594 | N13: =$N$10-M13 -> -58.459431
B14: 44131 | C14: 2191.4 | D14: =(C14-C15)/C15 -> 1.6554377 | E14: 0.053000817 | G14: 11 | H14: =_xlfn.NORM.INV(RAND(),N$6,N$7) -> 0.0027877019 | J14: 0.01 | K14: =100%-J14 -> 0.99 | L14: =_xlfn.PERCENTILE.INC($E$4:$E$2746,J14) -> -0.040442255 | M14: =$N$10*(1-L14) -> 2710.9763 | N14: =$N$10-M14 -> -105.37634
B15: 42192 | C15: 825.25 | D15: =(C15-C16)/C16 -> -0.67248735 | E15: 0.050872278 | G15: 12 | H15: =_xlfn.NORM.INV(RAND(),N$6,N$7) -> -0.0097790102 | J15: 0.005 | K15: =100%-J15 -> 0.995 | L15: =_xlfn.PERCENTILE.INC($E$4:$E$2746,J15) -> -0.047449989 | M15: =$N$10*(1-L15) -> 2729.2357 | N15: =$N$10-M15 -> -123.63569
B16: 44281 | C16: 2519.75 | D16: =(C16-C17)/C17 -> 0.60708591 | E16: 0.04893431 | G16: 13 | H16: =_xlfn.NORM.INV(RAND(),N$6,N$7) -> -0.00037883057
B17: 43972 | C17: 1567.9 | D17: =(C17-C18)/C18 -> -0.13330201 | E17: 0.048096527 | G17: 14 | H17: =_xlfn.NORM.INV(RAND(),N$6,N$7) -> 0.021599908 | J17: Monte Carlo Simulation
B18: 43943 | C18: 1809.05 | D18: =(C18-C19)/C19 -> 0.48197755 | E18: 0.048056312 | G18: 15 | H18: =_xlfn.NORM.INV(RAND(),N$6,N$7) -> 0.0011472728 | J18: Mean | N18: =AVERAGE(H4:H5003) -> 0.00054713942
B19: 42979 | C19: 1220.7 | D19: =(C19-C20)/C20 -> 0.30479397 | E19: 0.047002316 | G19: 16 | H19: =_xlfn.NORM.INV(RAND(),N$6,N$7) -> 0.0085524519 | J19: Std | N19: =_xlfn.STDEV.S(H4:H5003) -> 0.015056564
B20: 42690 | C20: 935.55 | D20: =(C20-C21)/C21 -> -0.48263562 | E20: 0.046593579 | G20: 17 | H20: =_xlfn.NORM.INV(RAND(),N$6,N$7) -> -0.015238203 | J20: Min | N20: =MIN(H4:H5003) -> -0.048836929
B21: 44050 | C21: 1808.3 | D21: =(C21-C22)/C22 -> -0.18383282 | E21: 0.045199699 | G21: 18 | H21: =_xlfn.NORM.INV(RAND(),N$6,N$7) -> 0.0027088428 | J21: Max | N21: =MAX(H4:H5003) -> 0.05013335
B22: 46105 | C22: 2215.6 | D22: =(C22-C23)/C23 -> 0.13112955 | E22: 0.04509434 | G22: 19 | H22: =_xlfn.NORM.INV(RAND(),N$6,N$7) -> 0.0060332725 | J22: current Price | N22: =N10 -> 2605.6
B23: 44064 | C23: 1958.75 | D23: =(C23-C24)/C24 -> -0.32285275 | E23: 0.044805974 | G23: 20 | H23: =_xlfn.NORM.INV(RAND(),N$6,N$7) -> 0.0056684664
B24: 45425 | C24: 2892.65 | D24: =(C24-C25)/C25 -> 0.17009486 | E24: 0.044711703 | G24: 21 | H24: =_xlfn.NORM.INV(RAND(),N$6,N$7) -> -0.036661075 | J24: Percentile | K24: Confidence | L24: VAR% | M24: Stock Price | N24: VAR(INR)
B25: 44271 | C25: 2472.15 | D25: =(C25-C26)/C26 -> 0.08809419 | E25: 0.044688134 | G25: 22 | H25: =_xlfn.NORM.INV(RAND(),N$6,N$7) -> 9.729192e-05 | J25: 0.05 | K25: =100%-J25 -> 0.95 | L25: =_xlfn.PERCENTILE.INC($H$4:$H$5003,J25) -> -0.023964871 | M25: =$N$10*(1-L25) -> 2668.0429 | N25: =$N$10-M25 -> -62.442869
B26: 45722 | C26: 2272 | D26: =(C26-C27)/C27 -> -0.0092015176 | E26: 0.043709948 | G26: 23 | H26: =_xlfn.NORM.INV(RAND(),N$6,N$7) -> -0.008857614 | J26: 0.01 | K26: =100%-J26 -> 0.99 | L26: =_xlfn.PERCENTILE.INC($H$4:$H$5003,J26) -> -0.035289848 | M26: =$N$10*(1-L26) -> 2697.5512 | N26: =$N$10-M26 -> -91.951227
B27: 46120 | C27: 2293.1 | D27: =(C27-C28)/C28 -> 0.87283567 | E27: 0.043314073 | G27: 24 | H27: =_xlfn.NORM.INV(RAND(),N$6,N$7) -> -0.0019621521 | J27: 0.005 | K27: =100%-J27 -> 0.995 | L27: =_xlfn.PERCENTILE.INC($H$4:$H$5003,J27) -> -0.037907189 | M27: =$N$10*(1-L27) -> 2704.371 | N27: =$N$10-M27 -> -98.770971
B28: 43032 | C28: 1224.4 | D28: =(C28-C29)/C29 -> -0.2671116 | E28: 0.043241171 | G28: 25 | H28: =_xlfn.NORM.INV(RAND(),N$6,N$7) -> 0.010044363
B29: 43921 | C29: 1670.65 | D29: =(C29-C30)/C30 -> -0.3627365 | E29: 0.042689967 | G29: 26 | H29: =_xlfn.NORM.INV(RAND(),N$6,N$7) -> 0.011937102
B30: 46155 | C30: 2621.6 | D30: =(C30-C31)/C31 -> 0.0081913625 | E30: 0.042510041 | G30: 27 | H30: =_xlfn.NORM.INV(RAND(),N$6,N$7) -> -0.023890221
B31: 45967 | C31: 2600.3 | D31: =(C31-C32)/C32 -> 1.1897263 | E31: 0.042413309 | G31: 28 | H31: =_xlfn.NORM.INV(RAND(),N$6,N$7) -> 0.0037895656
B32: 43397 | C32: 1187.5 | D32: =(C32-C33)/C33 -> -0.57120676 | E32: 0.042215201 | G32: 29 | H32: =_xlfn.NORM.INV(RAND(),N$6,N$7) -> 0.010184258
B33: 45973 | C33: 2769.4 | D33: =(C33-C34)/C34 -> 0.16916452 | E33: 0.041911211 | G33: 30 | H33: =_xlfn.NORM.INV(RAND(),N$6,N$7) -> 0.010159629
B34: 46122 | C34: 2368.7 | D34: =(C34-C35)/C35 -> -0.27582623 | E34: 0.041232582 | G34: 31 | H34: =_xlfn.NORM.INV(RAND(),N$6,N$7) -> 0.0098234173
B35: 44607 | C35: 3270.9 | D35: =(C35-C36)/C36 -> 2.7424485 | E35: 0.041024825 | G35: 32 | H35: =_xlfn.NORM.INV(RAND(),N$6,N$7) -> -0.0045960363
B36: 42345 | C36: 874 | D36: =(C36-C37)/C37 -> -0.66627847 | E36: 0.04047619 | G36: 33 | H36: =_xlfn.NORM.INV(RAND(),N$6,N$7) -> -0.0043629458
B37: 44292 | C37: 2618.95 | D37: =(C37-C38)/C38 -> 0.041580496 | E37: 0.039967438 | G37: 34 | H37: =_xlfn.NORM.INV(RAND(),N$6,N$7) -> -0.020107756
B38: 45947 | C38: 2514.4 | D38: =(C38-C39)/C39 -> 0.26727483 | E38: 0.039910666 | G38: 35 | H38: =_xlfn.NORM.INV(RAND(),N$6,N$7) -> 0.023987967
B39: 44075 | C39: 1984.1 | D39: =(C39-C40)/C40 -> 0.13403064 | E39: 0.039122237 | G39: 36 | H39: =_xlfn.NORM.INV(RAND(),N$6,N$7) -> 0.022736055
... B2746: 43913 | C2746: 1491.8 | D2746: =(C2746-C2747)/C2747 -> 0.97236729 | E2746: -0.14323455 | G2746: 2743 | H2746: =_xlfn.NORM.INV(RAND(),N$6,N$7) -> 0.012361601
B2747: 42157 | C2747: 756.35 | G2747: 2744 | H2747: =_xlfn.NORM.INV(RAND(),N$6,N$7) -> -0.0092708701
...

Sheet Altman Z Score
B3: ='Data Sheet'!B1 -> ASIAN PAINTS LTD
B4: =CONCATENATE("(",_xlfn.XLOOKUP(B3,'List Of Stocks'!B2:B5442,'List Of Stocks'!D2:D5442), " | ","BSE Code: ",_xlfn.XLOOKUP('Altman Z Score'!B3,'List Of Stocks'!B2:B5442,'List Of Stocks'!C2:C5442,,0)," ) ") -> (ASIANPAINT | BSE Code: 500820 )
B5: =CONCATENATE("INR", " ",'Data Sheet'!B8) -> INR 2605.6
B6: ="52 Week" & " "&"("&"High -" & " INR " &'Football Field Analysis'!Q10 & " " &"LOW - " & " INR " &'Football Field Analysis'!N10 &")" -> 52 Week (High - INR 2985.7 LOW - INR 2115)
B8: Altman's Z Score Analysis
B9: Asian Paints Ltd is an Indian multinational paint company, headquartered in Mumbai.The company is engaged in the business of manufacturing, selling and distribution of paints, coatings, products related to home décor, bath fittings and providing related services. Asian Paints is India's largest paints company by market share.The company has 27 paint manufacturing facilities in 15 countries, servicing consumers in over 60 countries. Asian Paints is also present in the home improvement and décor space in India
B16: Financial Summary
B67: Working Capital/Total Assets
C68: =HistoricalFS!F3 -> 43555 | D68: =HistoricalFS!G3 -> 43921 | E68: =HistoricalFS!H3 -> 44286 | F68: =HistoricalFS!I3 -> 44651 | G68: =HistoricalFS!J3 -> 45016 | H68: =HistoricalFS!K3 -> 45382 | I68: =HistoricalFS!L3 -> 45747
B69: Working Capital | C69: ='Data Sheet'!E65-'Data Sheet'!E60 -> 1515.34 | D69: ='Data Sheet'!F65-'Data Sheet'!F60 -> 2817.26 | E69: ='Data Sheet'!G65-'Data Sheet'!G60 -> 3121.11 | F69: ='Data Sheet'!H65-'Data Sheet'!H60 -> 6205.42 | G69: ='Data Sheet'!I65-'Data Sheet'!I60 -> 6873.09 | H69: ='Data Sheet'!J65-'Data Sheet'!J60 -> 6769.77 | I69: ='Data Sheet'!K65-'Data Sheet'!K60 -> 6490.76
B70: Total Assets | C70: ='Data Sheet'!E66 -> 16248.84 | D70: ='Data Sheet'!F66 -> 16137.97 | E70: ='Data Sheet'!G66 -> 20355.34 | F70: ='Data Sheet'!H66 -> 22958.43 | G70: ='Data Sheet'!I66 -> 25779.33 | H70: ='Data Sheet'!J66 -> 29900.77 | I70: ='Data Sheet'!K66 -> 30355.25
B71: Working Capital/Total Assets(A) | C71: =C69/C70 -> 0.09325835 | D71: =D69/D70 -> 0.17457338 | E71: =E69/E70 -> 0.15333126 | F71: =F69/F70 -> 0.27028939 | G71: =G69/G70 -> 0.26661244 | H71: =H69/H70 -> 0.22640788 | I71: =I69/I70 -> 0.2138266
B73: Retained Earnings/Total Assets
C74: =C68 -> 43555 | D74: =D68 -> 43921 | E74: =E68 -> 44286 | F74: =F68 -> 44651 | G74: =G68 -> 45016 | H74: =H68 -> 45382 | I74: =I68 -> 45747
B75: Retained Earnings | C75: =HistoricalFS!F36*HistoricalFS!F38*HistoricalFS!F44 -> 927.11 | D75: =HistoricalFS!G36*HistoricalFS!G38*HistoricalFS!G44 -> 1273.05 | E75: =HistoricalFS!H36*HistoricalFS!H38*HistoricalFS!H44 -> 1162.93 | F75: =HistoricalFS!I36*HistoricalFS!I38*HistoricalFS!I44 -> 952.06 | G75: =HistoricalFS!J36*HistoricalFS!J38*HistoricalFS!J44 -> 1303.52 | H75: =HistoricalFS!K36*HistoricalFS!K38*HistoricalFS!K44 -> 1542.59 | I75: =HistoricalFS!L36*HistoricalFS!L38*HistoricalFS!L44 -> 980.67
B76: =B70 -> Total Assets | C76: =C$70 -> 16248.84 | D76: =D$70 -> 16137.97 | E76: =E$70 -> 20355.34 | F76: =F$70 -> 22958.43 | G76: =G$70 -> 25779.33 | H76: =H$70 -> 29900.77 | I76: =I$70 -> 30355.25
B77: Retained Earnings/Total Assets(B) | C77: =C75/C76 -> 0.057056996 | D77: =D75/D76 -> 0.078885386 | E77: =E75/E76 -> 0.057131446 | F77: =F75/F76 -> 0.041468864 | G77: =G75/G76 -> 0.050564541 | H77: =H75/H76 -> 0.05159031 | I77: =I75/I76 -> 0.032306438
B79: EBIT/Total Assets
C80: =C74 -> 43555 | D80: =D74 -> 43921 | E80: =E74 -> 44286 | F80: =F74 -> 44651 | G80: =G74 -> 45016 | H80: =H74 -> 45382 | I80: =I74 -> 45747
B81: EBIT | C81: =HistoricalFS!F18-HistoricalFS!F24 -> 3142.8 | D81: =HistoricalFS!G18-HistoricalFS!G24 -> 3381.27 | E81: =HistoricalFS!H18-HistoricalFS!H24 -> 4064.33 | F81: =HistoricalFS!I18-HistoricalFS!I24 -> 3987.25 | G81: =HistoricalFS!J18-HistoricalFS!J24 -> 5401.82 | H81: =HistoricalFS!K18-HistoricalFS!K24 -> 6731.98 | I81: =HistoricalFS!L18-HistoricalFS!L24 -> 4979.87
B82: =B76 -> Total Assets | C82: =C76 -> 16248.84 | D82: =D76 -> 16137.97 | E82: =E76 -> 20355.34 | F82: =F76 -> 22958.43 | G82: =G76 -> 25779.33 | H82: =H76 -> 29900.77 | I82: =I76 -> 30355.25
B83: EBIT/Total Assets(C) | C83: =C81/C82 -> 0.19341688 | D83: =D81/D82 -> 0.20952264 | E83: =E81/E82 -> 0.19966898 | F83: =F81/F82 -> 0.17367259 | G83: =G81/G82 -> 0.20954074 | H83: =H81/H82 -> 0.22514403 | I83: =I81/I82 -> 0.16405301
B85: Market cap/Long Term Liabilities
C86: =C80 -> 43555 | D86: =D80 -> 43921 | E86: =E80 -> 44286 | F86: =F80 -> 44651 | G86: =G80 -> 45016 | H86: =H80 -> 45382 | I86: =I80 -> 45747
B87: Market Cap | C87: =('Data Sheet'!E70*'Data Sheet'!E90)/10000000 -> 143179.45 | D87: =('Data Sheet'!F70*'Data Sheet'!F90)/10000000 -> 159850.31 | E87: =('Data Sheet'!G70*'Data Sheet'!G90)/10000000 -> 243386.85 | F87: =('Data Sheet'!H70*'Data Sheet'!H90)/10000000 -> 295428.12 | G87: =('Data Sheet'!I70*'Data Sheet'!I90)/10000000 -> 264896.86 | H87: =('Data Sheet'!J70*'Data Sheet'!J90)/10000000 -> 273059.63 | I87: =('Data Sheet'!K70*'Data Sheet'!K90)/10000000 -> 224514.63
B88: Long Term Liability | C88: ='Data Sheet'!E59 -> 1319.6 | D88: ='Data Sheet'!F59 -> 1118.5 | E88: ='Data Sheet'!G59 -> 1093.12 | F88: ='Data Sheet'!H59 -> 1586.88 | G88: ='Data Sheet'!I59 -> 1932.62 | H88: ='Data Sheet'!J59 -> 2474.38 | I88: ='Data Sheet'!K59 -> 2290.29
B89: Market cap/Long Term Liabilities(D) | C89: =C87/C88 -> 108.50216 | D89: =D87/D88 -> 142.9149 | E89: =E87/E88 -> 222.65337 | F89: =F87/F88 -> 186.16916 | G89: =G87/G88 -> 137.06619 | H89: =H87/H88 -> 110.35477 | I89: =I87/I88 -> 98.028909
B93: Sales/Total Assets
C94: =C86 -> 43555 | D94: =D86 -> 43921 | E94: =E86 -> 44286 | F94: =F86 -> 44651 | G94: =G86 -> 45016 | H94: =H86 -> 45382 | I94: =I86 -> 45747
B95: Sales | C95: ='Data Sheet'!E17 -> 19240.13 | D95: ='Data Sheet'!F17 -> 20211.25 | E95: ='Data Sheet'!G17 -> 21712.79 | F95: ='Data Sheet'!H17 -> 29101.28 | G95: ='Data Sheet'!I17 -> 34488.59 | H95: ='Data Sheet'!J17 -> 35494.73 | I95: ='Data Sheet'!K17 -> 33905.62
B96: Total Assets | C96: =C82 -> 16248.84 | D96: =D82 -> 16137.97 | E96: =E82 -> 20355.34 | F96: =F82 -> 22958.43 | G96: =G82 -> 25779.33 | H96: =H82 -> 29900.77 | I96: =I82 -> 30355.25
B97: Sales/Total Assets(E) | C97: =C95/C96 -> 1.1840925 | D97: =D95/D96 -> 1.2524035 | E97: =E95/E96 -> 1.0666877 | F97: =F95/F96 -> 1.267564 | G97: =G95/G96 -> 1.3378389 | H97: =H95/H96 -> 1.1870841 | I97: =I95/I96 -> 1.1169607
B99: Altman's Z Score
C100: =C94 -> 43555 | D100: =D94 -> 43921 | E100: =E94 -> 44286 | F100: =F94 -> 44651 | G100: =G94 -> 45016 | H100: =H94 -> 45382 | I100: =I94 -> 45747
B101: Final Score | C101: =(C71*1.2)+(C77*1.4)+(C83*3.3)+(C89*0.6)+(C97*1) -> 67.115456 | D101: =(D71*1.2)+(D77*1.4)+(D83*3.3)+(D89*0.6)+(D97*1) -> 88.012694 | E101: =(E71*1.2)+(E77*1.4)+(E83*3.3)+(E89*0.6)+(E97*1) -> 135.5816 | F101: =(F71*1.2)+(F77*1.4)+(F83*3.3)+(F89*0.6)+(F97*1) -> 113.92459 | G101: =(G71*1.2)+(G77*1.4)+(G83*3.3)+(G89*0.6)+(G97*1) -> 84.659762 | H101: =(H71*1.2)+(H77*1.4)+(H83*3.3)+(H89*0.6)+(H97*1) -> 68.486836 | I101: =(I71*1.2)+(I77*1.4)+(I83*3.3)+(I89*0.6)+(I97*1) -> 60.777502
B102: Financial Stability | C102: =IF(C101<1.81,"Distressed",IF(C101>3,"Strong","Grey Zone")) -> Strong | D102: =IF(D101<1.81,"Distressed",IF(D101>3,"Strong","Grey Zone")) -> Strong | E102: =IF(E101<1.81,"Distressed",IF(E101>3,"Strong","Grey Zone")) -> Strong | F102: =IF(F101<1.81,"Distressed",IF(F101>3,"Strong","Grey Zone")) -> Strong | G102: =IF(G101<1.81,"Distressed",IF(G101>3,"Strong","Grey Zone")) -> Strong | H102: =IF(H101<1.81,"Distressed",IF(H101>3,"Strong","Grey Zone")) -> Strong | I102: =IF(I101<1.81,"Distressed",IF(I101>3,"Strong","Grey Zone")) -> Strong

Sheet DCF>
B2: Calculation of PV of FCFF | E2: ='Intrisic Growth'!I2 -> 45717 | F2: =E2+365 -> 46082 | G2: =F2+365 -> 46447 | H2: =G2+366 -> 46813 | I2: =H2+365 -> 47178 | J2: =I2+365 -> 47543
B4: EBIT | E4: =IFERROR('Data Sheet'!K34-'Data Sheet'!K26,0) -> 5287.61 | F4: =E4*(1+$D$14) -> 6384.7891 | G4: =F4*(1+$D$14) -> 7709.6328 | H4: =G4*(1+$D$14) -> 9309.3816 | I4: =H4*(1+$D$14) -> 11241.078 | J4: =I4*(1+$D$14) -> 13573.602
B5: Tax Rate | E5: 0.25 | F5: =$E$5 -> 0.25 | G5: =$E$5 -> 0.25 | H5: =$E$5 -> 0.25 | I5: =$E$5 -> 0.25 | J5: =$E$5 -> 0.25
B6: EBIT(1-Tax) | E6: =E4*(1-E5) -> 3965.7075 | F6: =E6*(1+$D$14) -> 4788.5918 | G6: =F6*(1+$D$14) -> 5782.2246 | H6: =G6*(1+$D$14) -> 6982.0362 | I6: =H6*(1+$D$14) -> 8430.8087 | J6: =I6*(1+$D$14) -> 10180.202
B7: Less: Reinvestment Rate | E7: 0.4914
B8: Free Cash Flow to Firm(FCFF) | E8: =E6*(1-E7) -> 2016.9588 | F8: =E8*(1+$D$14) -> 2435.4778 | G8: =F8*(1+$D$14) -> 2940.8394 | H8: =G8*(1+$D$14) -> 3551.0636 | I8: =H8*(1+$D$14) -> 4287.9093 | J8: =I8*(1+$D$14) -> 5177.6505
B9: Mid Year Convention | F9: 0.5 | G9: =F9+1 -> 1.5 | H9: =G9+1 -> 2.5 | I9: =H9+1 -> 3.5 | J9: =I9+1 -> 4.5
B10: Discounting Factor | F10: =1/(1+$D$16)^F9 -> 0.9419742 | G10: =1/(1+$D$16)^G9 -> 0.8358282 | H10: =1/(1+$D$16)^H9 -> 0.74164322 | I10: =1/(1+$D$16)^I9 -> 0.65807144 | J10: =1/(1+$D$16)^J9 -> 0.58391691
B12: PV of FCFF | F12: =F8*F10 -> 2294.1572 | G12: =G8*G10 -> 2458.0365 | H12: =H8*H10 -> 2633.6222 | I12: =I8*I10 -> 2821.7506 | J12: =J8*J10 -> 3023.3177
B14: Expected Growth | D14: 0.2075
B15: Terminal Growth | D15: 0.045 | F15: Sensitivy Analysis
B16: WACC | D16: =WACC!J43 -> 0.126995 | F16: =D37 -> 586.37307 | G16: 0.12 | H16: 0.1269 | I16: 0.135 | J16: 0.14
F17: 0.03 | G17: 545.08788 | H17: 514.97547 | I17: 484.67602 | J17: 468.20006
B18: Calculation of Terminal Value | F18: 0.04 | G18: 597.94826 | H18: 560.17347 | I18: 522.83088 | J18: 502.79958
F19: 0.045 | G19: 629.66448 | H19: 586.91147 | I19: 545.08788 | J19: 522.83088
B20: FCFF(n+1) | D20: =J8*(1+D14) -> 6252.013 | F20: 0.05 | G20: 665.9116 | H20: 617.12647 | I20: 569.96335 | J20: 545.08788
B21: WACC | D21: =D16 -> 0.126995 | F21: 0.06 | G21: 756.52939 | H21: 691.10578 | I21: 629.66448 | J21: 597.94826
B22: Terminal Growth Rate | D22: =D15 -> 0.045 | F22: 0.07 | G22: 883.39429 | H22: 791.08837 | I22: 707.73519 | J22: 665.9116
B24: Terminal Value | D24: =D20/(D21-D22) -> 76248.712
B26: Calculation of Enterprise Value
B28: PV of FCFF | D28: =SUM(F12:J12) -> 13230.884
B29: PV Terminal Value | D29: =D24*J10 -> 44522.912
B30: Value of Operating Activities | D30: =SUM(D28:D29) -> 57753.796
B32: Add: Cash | D32: ='Data Sheet'!K69 -> 781.98
B33: Less: debt | D33: =SUM('Raw FS'!N7:N9) -> 2291
B34: Value of Equity | D34: =D30+D32-D33 -> 56244.776
B35: NO. of Shares | D35: ='Data Sheet'!B6 -> 95.91978
B37: Equity Value Per Share | D37: =D34/D35 -> 586.37307
B39: Share Price | D39: ='Data Sheet'!B8 -> 2605.6
B40: Discount/Premium | D40: =D39/D37-1 -> 3.4435874

Sheet WACC
B2: Weighted Average Cost of Capital
B4: All figures are in INR unless stated otherwise.
B6: Peer Comps
G7: Debt/ | H7: Debt/ | I7: Levered | J7: Unlevered
B8: Name | C8: Country | D8: Total Debt | E8: Total Equity | F8: Tax Rate 1 | G8: Equity | H8: Capital | I8: Beta 2 | J8: Beta 3
B10: Asian Paints | C10: India | D10: ='Relative Data'!G3 -> 2291 | E10: ='Beta - Comps'!E4 -> 249928.58 | F10: 0.25 | G10: =D10/E10 -> 0.0091666187 | H10: =D10/(D10+E10) -> 0.0090833551 | I10: ='Beta - Regression'!J13 -> 1.0559519 | J10: =I10/(1+(1-F10)*G10) -> 1.0487419
B11: Berger Paints | C11: India | D11: ='Relative Data'!G4 -> 635.13 | E11: ='Beta - Comps'!E5 -> 63791.48 | F11: =$F$10 -> 0.25 | G11: =D11/E11 -> 0.0099563453 | H11: =D11/(D11+E11) -> 0.0098581937 | I11: 1.04 | J11: =I11/(1+(1-F11)*G11) -> 1.0322916
B12: Kansai Nerolac | C12: India | D12: ='Relative Data'!G5 -> 302.73 | E12: ='Beta - Comps'!E6 -> 17422.14 | F12: =$F$10 -> 0.25 | G12: =D12/E12 -> 0.017376166 | H12: =D12/(D12+E12) -> 0.017079392 | I12: 1.053 | J12: =I12/(1+(1-F12)*G12) -> 1.0394537
B13: JSW Dulux | C13: India | D13: ='Relative Data'!G6 -> 79.1 | E13: ='Beta - Comps'!E7 -> 14647.68 | F13: =$F$10 -> 0.25 | G13: =D13/E13 -> 0.0054001726 | H13: =D13/(D13+E13) -> 0.0053711674 | I13: 0.6 | J13: =I13/(1+(1-F13)*G13) -> 0.59757972
B14: Indigo Paints | C14: India | D14: ='Relative Data'!G7 -> 18.37 | E14: ='Beta - Comps'!E8 -> 4825.19 | F14: =$F$10 -> 0.25 | G14: =D14/E14 -> 0.003807104 | H14: =D14/(D14+E14) -> 0.0037926649 | I14: 1.2 | J14: =I14/(1+(1-F14)*G14) -> 1.1965834
E16: Average | F16: =AVERAGE(F10:F14) -> 0.25 | G16: =AVERAGE(G10:G14) -> 0.0091412813 | H16: =AVERAGE(H10:H14) -> 0.0090369546 | I16: =AVERAGE(I10:I14) -> 0.98979039 | J16: =AVERAGE(J10:J14) -> 0.98293005
E17: Median | F17: =MEDIAN(F10:F14) -> 0.25 | G17: =MEDIAN(G10:G14) -> 0.0091666187 | H17: =MEDIAN(H10:H14) -> 0.0090833551 | I17: =MEDIAN(I10:I14) -> 1.053 | J17: =MEDIAN(J10:J14) -> 1.0394537
B20: Cost of Debt | G20: Cost of Equity
B22: Pre-tax Cost of Debt | E22: 0.076 | G22: Risk Free Rate | J22: 0.0685
B23: Tax Rate | E23: =F17 -> 0.25 | G23: Equity Risk Premium | J23: =Rm!G11-WACC!J22 -> 0.056
B24: After Tax Cost of Debt | E24: =E22*(1-E23) -> 0.057 | G24: Levered Beta 4 | J24: ='Beta - Regression'!J13 -> 1.0559519
G25: Cost of Equity | J25: =J22+(J23*J24) -> 0.12763331
B28: Capital Structure | G28: Levered Beta
D30: Current | E30: Target | G30: Comps Median Unlevered Beta | J30: =J17 -> 1.0394537
B31: Total Debt | C31: =D10 -> 2291 | D31: =C31/$C$33 -> 0.0090833551 | E31: =H16 -> 0.0090369546 | G31: Target Debt/ Equity | J31: =E35 -> 0.0091193659
B32: Market Capitalization | C32: =E10 -> 249928.58 | D32: =C32/$C$33 -> 0.99091664 | E32: =E33-E31 -> 0.99096305 | G32: Tax Rate | J32: =E23 -> 0.25
B33: Total Capitalization | C33: =SUM(C31:C32) -> 252219.58 | D33: =C33/$C$33 -> 1 | E33: =D33 -> 1 | G33: Levered Beta | J33: =J30*(1+(1-J31)*J32) -> 1.2969473
B35: Debt / Equity | D35: =D31/D32 -> 0.0091666187 | E35: =E31/E32 -> 0.0091193659 | G35: Weighted Average Cost of Capital
B37: 1. Tax Rate considered as Marginal Tax Rate for the country | G37: Cost of Equity | J37: =J25 -> 0.12763331
B38: 2. Levered Beta is based on 5 year monthly data | G38: Equity Weight | J38: =E32 -> 0.99096305
B39: 3. Unlevered Beta = Levered Beta/(1+(1-Tax Rate) x Debt/Equity)
B40: 4. Levered Beta = Unlevered Beta/(1+(1-Tax Rate) x Debt/Equity) | G40: Cost of Debt | J40: =E24 -> 0.057
B41: 5.All Beta are calculated on 5 year monthly basis | G41: Debt Weight | J41: =E31 -> 0.0090369546
G43: WACC | J43: =(J37*J38)+(J40*J41) -> 0.126995

Sheet Intrisic Growth
A2: # | B2: Calculation of ROIC | E2: ='Raw FS'!J$2 -> 44256 | F2: ='Raw FS'!K$2 -> 44621 | G2: ='Raw FS'!L$2 -> 44986 | H2: ='Raw FS'!M$2 -> 45352 | I2: ='Raw FS'!N$2 -> 45717
B4: Current Assets
B5: ='Raw FS'!B35 -> Inventories | E5: ='Raw FS'!J35 -> 3799 | F5: ='Raw FS'!K35 -> 6153 | G5: ='Raw FS'!L35 -> 6211 | H5: ='Raw FS'!M35 -> 5923 | I5: ='Raw FS'!N35 -> 6719
B6: ='Raw FS'!B36 -> Trade receivables | E6: ='Raw FS'!J36 -> 2602 | F6: ='Raw FS'!K36 -> 3871 | G6: ='Raw FS'!L36 -> 4637 | H6: ='Raw FS'!M36 -> 4889 | I6: ='Raw FS'!N36 -> 4314
B7: ='Raw FS'!B38 -> Loans n Advances | E7: ='Raw FS'!J38 -> 11 | F7: ='Raw FS'!K38 -> 8 | G7: ='Raw FS'!L38 -> 12 | H7: ='Raw FS'!M38 -> 17 | I7: ='Raw FS'!N38 -> 22
B8: ='Raw FS'!B39 -> Other asset items | E8: ='Raw FS'!J39 -> 2555 | F8: ='Raw FS'!K39 -> 2869 | G8: ='Raw FS'!L39 -> 3024 | H8: ='Raw FS'!M39 -> 3555 | I8: ='Raw FS'!N39 -> 3319
B9: Total Current Assets | E9: =SUM(E5:E8) -> 8967 | F9: =SUM(F5:F8) -> 12901 | G9: =SUM(G5:G8) -> 13884 | H9: =SUM(H5:H8) -> 14384 | I9: =SUM(I5:I8) -> 14374
B11: Current Liabilities
B12: ='Raw FS'!B13 -> Trade Payables | E12: ='Raw FS'!J13 -> 3379 | F12: ='Raw FS'!K13 -> 4164 | G12: ='Raw FS'!L13 -> 3635 | H12: ='Raw FS'!M13 -> 3831 | I12: ='Raw FS'!N13 -> 3848
B13: ='Raw FS'!B14 -> Advance from Customers | E13: ='Raw FS'!J14 -> 41 | F13: ='Raw FS'!K14 -> 76 | G13: ='Raw FS'!L14 -> 108 | H13: ='Raw FS'!M14 -> 154 | I13: ='Raw FS'!N14 -> 173
B14: ='Raw FS'!B15 -> Other liability items | E14: ='Raw FS'!J15 -> 2613 | F14: ='Raw FS'!K15 -> 2932 | G14: ='Raw FS'!L15 -> 3657 | H14: ='Raw FS'!M15 -> 4017 | I14: ='Raw FS'!N15 -> 3985
B15: Total Current Liabilities | E15: =SUM(E12:E14) -> 6033 | F15: =SUM(F12:F14) -> 7172 | G15: =SUM(G12:G14) -> 7400 | H15: =SUM(H12:H14) -> 8002 | I15: =SUM(I12:I14) -> 8006
A17: # | B17: Net Working Capital | E17: =E9-E15 -> 2934 | F17: =F9-F15 -> 5729 | G17: =G9-G15 -> 6484 | H17: =H9-H15 -> 6382 | I17: =I9-I15 -> 6368
B19: Non Current Assets
B20: ='Raw FS'!B19 -> Land | E20: ='Raw FS'!J19 -> 644 | F20: ='Raw FS'!K19 -> 644 | G20: ='Raw FS'!L19 -> 804 | H20: ='Raw FS'!M19 -> 1126 | I20: ='Raw FS'!N19 -> 1050
B21: ='Raw FS'!B20 -> Building | E21: ='Raw FS'!J20 -> 2249 | F21: ='Raw FS'!K20 -> 2325 | G21: ='Raw FS'!L20 -> 2883 | H21: ='Raw FS'!M20 -> 3390 | I21: ='Raw FS'!N20 -> 4136
B22: ='Raw FS'!B21 -> Plant Machinery | E22: ='Raw FS'!J21 -> 4340 | F22: ='Raw FS'!K21 -> 4531 | G22: ='Raw FS'!L21 -> 4825 | H22: ='Raw FS'!M21 -> 5422 | I22: ='Raw FS'!N21 -> 7576
B23: ='Raw FS'!B22 -> Equipments | E23: ='Raw FS'!J22 -> 243 | F23: ='Raw FS'!K22 -> 253 | G23: ='Raw FS'!L22 -> 270 | H23: ='Raw FS'!M22 -> 298 | I23: ='Raw FS'!N22 -> 325
B24: ='Raw FS'!B23 -> Furniture n fittings | E24: ='Raw FS'!J23 -> 99 | F24: ='Raw FS'!K23 -> 113 | G24: ='Raw FS'!L23 -> 146 | H24: ='Raw FS'!M23 -> 175 | I24: ='Raw FS'!N23 -> 203
B25: ='Raw FS'!B24 -> Vehicles | E25: ='Raw FS'!J24 -> 38 | F25: ='Raw FS'!K24 -> 32 | G25: ='Raw FS'!L24 -> 36 | H25: ='Raw FS'!M24 -> 40 | I25: ='Raw FS'!N24 -> 39
B26: ='Raw FS'!B25 -> Intangible Assets | E26: ='Raw FS'!J25 -> 476 | F26: ='Raw FS'!K25 -> 345 | G26: ='Raw FS'!L25 -> 422 | H26: ='Raw FS'!M25 -> 850 | I26: ='Raw FS'!N25 -> 827
B27: ='Raw FS'!B26 -> Other fixed assets | E27: ='Raw FS'!J26 -> 302 | F27: ='Raw FS'!K26 -> 294 | G27: ='Raw FS'!L26 -> 289 | H27: ='Raw FS'!M26 -> 321 | I27: ='Raw FS'!N26 -> 328
B29: Gross Block | E29: =SUM(E20:E28) -> 8391 | F29: =SUM(F20:F28) -> 8537 | G29: =SUM(G20:G28) -> 9675 | H29: =SUM(H20:H28) -> 11622 | I29: =SUM(I20:I28) -> 14484
B30: Accumulated Depreciation | E30: =-'Raw FS'!J28 -> -2533 | F30: =-'Raw FS'!K28 -> -3019 | G30: =-'Raw FS'!L28 -> -3905 | H30: =-'Raw FS'!M28 -> -4475 | I30: =-'Raw FS'!N28 -> -5264
A31: # | B31: Net Non Current Assets | E31: =SUM(E29:E30) -> 5858 | F31: =SUM(F29:F30) -> 5518 | G31: =SUM(G29:G30) -> 5770 | H31: =SUM(H29:H30) -> 7147 | I31: =SUM(I29:I30) -> 9220
A33: # | B33: Invested Capital | E33: =E31+E17 -> 8792 | F33: =F31+F17 -> 11247 | G33: =G31+G17 -> 12254 | H33: =H31+H17 -> 13529 | I33: =I31+I17 -> 15588
B34: EBIT | E34: =(HistoricalFS!H27+HistoricalFS!H21) -> 4064.33 | F34: =(HistoricalFS!I27+HistoricalFS!I21) -> 3987.25 | G34: =(HistoricalFS!J27+HistoricalFS!J21) -> 5401.82 | H34: =(HistoricalFS!K27+HistoricalFS!K21) -> 6731.98 | I34: =(HistoricalFS!L27+HistoricalFS!L21) -> 4979.87
A36: # | B36: ROIC | E36: =E34/E33 -> 0.46227593 | F36: =F34/F33 -> 0.35451676 | G36: =G34/G33 -> 0.44082096 | H36: =H34/H33 -> 0.49759627 | I36: =I34/I33 -> 0.31946818
A39: # | B39: Calculation of Reinvestment Rate | E39: ='Raw FS'!J$2 -> 44256 | F39: ='Raw FS'!K$2 -> 44621 | G39: ='Raw FS'!L$2 -> 44986 | H39: ='Raw FS'!M$2 -> 45352 | I39: ='Raw FS'!N$2 -> 45717
B41: Net Capex | E41: =-SUM('Raw FS'!J54:J55) -> 261 | F41: =-SUM('Raw FS'!K54:K55) -> 511 | G41: =-SUM('Raw FS'!L54:L55) -> 1420 | H41: =-SUM('Raw FS'!M54:M55) -> 2491 | I41: =-SUM('Raw FS'!N54:N55) -> 1820
B42: Change in Working Capital | F42: =F17-E17 -> 2795 | G42: =G17-F17 -> 755 | H42: =H17-G17 -> -102 | I42: =I17-H17 -> -14
B44: EBIT | E44: =E34 -> 4064.33 | F44: =F34 -> 3987.25 | G44: =G34 -> 5401.82 | H44: =H34 -> 6731.98 | I44: =I34 -> 4979.87
B45: Marginal Tax Rate | E45: 0.25 | F45: 0.25 | G45: 0.25 | H45: 0.25 | I45: 0.25
B46: EBIT(1-T) | E46: =E44*(1-E45) -> 3048.2475 | F46: =F44*(1-F45) -> 2990.4375 | G46: =G44*(1-G45) -> 4051.365 | H46: =H44*(1-H45) -> 5048.985 | I46: =I44*(1-I45) -> 3734.9025
B48: Reinvestment | F48: =SUM(F41:F42) -> 3306 | G48: =SUM(G41:G42) -> 2175 | H48: =SUM(H41:H42) -> 2389 | I48: =SUM(I41:I42) -> 1806
B50: Reinvestment Rate | F50: =F48/F46 -> 1.1055239 | G50: =G48/G46 -> 0.5368561 | H50: =H48/H46 -> 0.47316441 | I50: =I48/I46 -> 0.48354676
H52: 4 Year Average | I52: =AVERAGE(F50:I50) -> 0.64977278
H53: 4 Year Median | I53: =MEDIAN(F50:I50) -> 0.51020143
A55: # | B55: Calculation of Growth Rate | E55: ='Raw FS'!J$2 -> 44256 | F55: ='Raw FS'!K$2 -> 44621 | G55: ='Raw FS'!L$2 -> 44986 | H55: ='Raw FS'!M$2 -> 45352 | I55: ='Raw FS'!N$2 -> 45717
B57: Reinvestment Rate | F57: =F50 -> 1.1055239 | G57: =G50 -> 0.5368561 | H57: =H50 -> 0.47316441 | I57: =I50 -> 0.48354676
...

Sheet Beta - Regression
E2: needs correction
B3: Regression Beta - 5 Years Monthly
B5: ='Data Sheet'!B1 &" - " & "Weekly Returns" -> ASIAN PAINTS LTD - Weekly Returns | F5: NIFTY Returns | I5: Beta Drifting | L5: Beta 1 | M5: =SLOPE(D8:D112,G8:G112) -> 1.0746026
B6: Date | C6: Closing Price | D6: Return | F6: Closing Price | G6: Return | L6: Beta 2 | M6: =_xlfn.COVARIANCE.S(D7:D112,G7:G112)/VAR(G7:G112) -> 1.0746026
B7: 46174 | C7: 2645.2 | F7: 24021.65 | I7: Levered Raw Beta | J7: =M5 -> 1.0746026
B8: 46143 | C8: 2671.6 | D8: =C8/C7-1 -> 0.0099803418 | F8: 23547.75 | G8: =F8/F7-1 -> -0.019728037 | I8: Raw Beta Weight | J8: 0.75 | L8: Beta 3
B9: 46113 | C9: 2444.5 | D9: =C9/C8-1 -> -0.08500524 | F9: 23997.55 | G9: =F9/F8-1 -> 0.019101613
B10: 46082 | C10: 2165.2 | D10: =C10/C9-1 -> -0.11425649 | F10: 22331.4 | G10: =F10/F9-1 -> -0.069430004 | I10: Market Beta | J10: 1
B11: 46054 | C11: 2376.2 | D11: =C11/C10-1 -> 0.097450582 | F11: 25178.65 | G11: =F11/F10-1 -> 0.12749984 | I11: Market Beta Weight | J11: 0.25
B12: 46023 | C12: 2428.3 | D12: =C12/C11-1 -> 0.021925764 | F12: 25320.65 | G12: =F12/F11-1 -> 0.0056396987
B13: 45992 | C13: 2769.5 | D13: =C13/C12-1 -> 0.14050982 | F13: 26129.6 | G13: =F13/F12-1 -> 0.031948232 | I13: Adjusted Beta | J13: =(J7*J8)+(J10*J11) -> 1.0559519
B14: 45962 | C14: 2874.4 | D14: =C14/C13-1 -> 0.037876873 | F14: 26202.95 | G14: =F14/F13-1 -> 0.0028071612
B15: 45931 | C15: 2510.8 | D15: =C15/C14-1 -> -0.12649596 | F15: 25722.1 | G15: =F15/F14-1 -> -0.018350987
B16: 45901 | C16: 2350 | D16: =C16/C15-1 -> -0.064043333 | F16: 24611.1 | G16: =F16/F15-1 -> -0.04319243
B17: 45870 | C17: 2518.6 | D17: =C17/C16-1 -> 0.071744681 | F17: 24426.85 | G17: =F17/F16-1 -> -0.0074864594
B18: 45839 | C18: 2396.1 | D18: =C18/C17-1 -> -0.048638132 | F18: 24768.35 | G18: =F18/F17-1 -> 0.013980517
B19: 45809 | C19: 2341.1 | D19: =C19/C18-1 -> -0.022953967 | F19: 25517.05 | G19: =F19/F18-1 -> 0.030228094
B20: 45778 | C20: 2259.1 | D20: =C20/C19-1 -> -0.03502627 | F20: 24750.7 | G20: =F20/F19-1 -> -0.03003286
B21: 45748 | C21: 2425.7 | D21: =C21/C20-1 -> 0.073746182 | F21: 24334.2 | G21: =F21/F20-1 -> -0.016827807
B22: 45717 | C22: 2340.65 | D22: =C22/C21-1 -> -0.035062044 | F22: 23519.35 | G22: =F22/F21-1 -> -0.033485794
B23: 45689 | C23: 2179.75 | D23: =C23/C22-1 -> -0.068741589 | F23: 22124.7 | G23: =F23/F22-1 -> -0.059297982
B24: 45658 | C24: 2300.8 | D24: =C24/C23-1 -> 0.055533892 | F24: 23508.4 | G24: =F24/F23-1 -> 0.062540961
B25: 45627 | C25: 2281.35 | D25: =C25/C24-1 -> -0.0084535814 | F25: 23644.8 | G25: =F25/F24-1 -> 0.0058021813
... B66: 44378 | C66: 2958.45 | D66: =C66/C65-1 -> -0.075874241 | F66: 15763.05 | G66: =F66/F65-1 -> -0.079916765

Sheet Relative valuation
B3: Amount in crores
B4: Comparable Company Valuations
D6: Market Data | K6: Financials | O6: Valuation
B7: Company | C7: Ticker | D7: Share prize | E7: Shares Outstanding | F7: Equity Value | G7: Net Debt | H7: Enterprise Value | K7: Revenue | L7: EBITDA | M7: Net Income | O7: EV/Revenue | P7: EV/EBITDA | Q7: P/E
B9: Asian Paints | D9: ='Relative Data'!D3 -> 2605.6 | E9: ='Relative Data'!E3 -> 95.91978 | F9: =E9*D9 -> 249928.58 | G9: ='Relative Data'!I3 -> 1509.02 | H9: =G9+F9 -> 251437.6 | K9: ='Data Sheet'!K17 -> 33905.62 | L9: ='Relative Data'!L3 -> 6313.95 | M9: ='Relative Data'!M3 -> 3667.23 | O9: ='Relative Data'!J3/'Relative Data'!K3 -> 7.4158089 | P9: ='Relative Data'!$J3/'Relative valuation'!L9 -> 39.822552 | Q9: ='Relative Data'!O3 -> 68.151869
B10: Berger Paints | D10: 545.75 | E10: 116.60027 | F10: =E10*D10 -> 63634.6 | G10: 329.82 | H10: =G10+F10 -> 63964.42 | K10: ='Relative Data'!K4 -> 11880.25 | L10: ='Relative Data'!L4 -> 1990.8005 | M10: ='Relative Data'!M4 -> 1165.8959 | O10: ='Relative Data'!$J4/'Relative valuation'!K10 -> 5.3840971 | P10: ='Relative Data'!$J4/'Relative valuation'!L10 -> 32.13 | Q10: ='Relative Data'!O4 -> 54.58
B11: Kansai Nerolac | D11: 216 | E11: 80.871435 | F11: =E11*D11 -> 17468.23 | G11: 76.95 | H11: =G11+F11 -> 17545.18 | K11: ='Relative Data'!K5 -> 8051.91 | L11: ='Relative Data'!L5 -> 1049.3529 | M11: ='Relative Data'!M5 -> 579.18534 | O11: ='Relative Data'!$J5/'Relative valuation'!K11 -> 2.1790085 | P11: ='Relative Data'!$J5/'Relative valuation'!L11 -> 16.72 | Q11: ='Relative Data'!O5 -> 30.16
B12: JSW Dulux | D12: 3205.35 | E12: 4.5540331 | F12: =E12*D12 -> 14597.27 | G12: -244.6 | H12: =G12+F12 -> 14352.67 | K12: ='Relative Data'!K6 -> 3599.2 | L12: ='Relative Data'!L6 -> 521.15723 | M12: ='Relative Data'!M6 -> 361.13978 | O12: ='Relative Data'!$J6/'Relative valuation'!K12 -> 3.9877389 | P12: ='Relative Data'!$J6/'Relative valuation'!L12 -> 27.54 | Q12: ='Relative Data'!O6 -> 40.42
B13: Indigo Paints | D13: 1060.5 | E13: 4.7675719 | F13: =E13*D13 -> 5056.01 | G13: -10.18 | H13: =G13+F13 -> 5045.83 | K13: ='Relative Data'!K7 -> 1330.12 | L13: ='Relative Data'!L7 -> 258.89328 | M13: ='Relative Data'!M7 -> 149.67466 | O13: ='Relative Data'!$J7/'Relative valuation'!K13 -> 3.7935149 | P13: ='Relative Data'!$J7/'Relative valuation'!L13 -> 19.49 | Q13: ='Relative Data'!O7 -> 33.78
B15: High | O15: =MAX(O9:O13) -> 7.4158089 | P15: =MAX(P9:P13) -> 39.822552 | Q15: =MAX(Q9:Q13) -> 68.151869
B16: 75th Percentile | O16: =QUARTILE(O9:O13,3) -> 5.3840971 | P16: =QUARTILE(P9:P13,3) -> 32.13 | Q16: =QUARTILE(Q9:Q13,3) -> 54.58
B17: Average | O17: =AVERAGE(O9:O13) -> 4.5520337 | P17: =AVERAGE(P9:P13) -> 27.14051 | Q17: =AVERAGE(Q9:Q13) -> 45.418374
B18: Median | O18: =MEDIAN(O9:O13) -> 3.9877389 | P18: =MEDIAN(P9:P13) -> 27.54 | Q18: =MEDIAN(Q9:Q13) -> 40.42
B19: 25th Percentile | O19: =QUARTILE(O9:O13,1) -> 3.7935149 | P19: =QUARTILE(P9:P13,1) -> 19.49 | Q19: =QUARTILE(Q9:Q13,1) -> 33.78
B20: Low | O20: =MIN(O9:O13) -> 2.1790085 | P20: =MIN(P9:P13) -> 16.72 | Q20: =MIN(Q9:Q13) -> 30.16
B22: Comparable Company Valuations | O22: EV/Revenue | P22: EV/EBITDA | Q22: P/E
B24: Implied Enterprise Value | O24: =O18*K9 -> 135206.76 | P24: =P18*L9 -> 173886.18 | Q24: =Q26+Q25 -> 149738.46
B25: Net Debt | O25: =$G$9 -> 1509.02 | P25: =$G$9 -> 1509.02 | Q25: =$G$9 -> 1509.02
B26: Implied Market Value | O26: =O24-O25 -> 133697.74 | P26: =P24-P25 -> 172377.16 | Q26: =Q18*M9 -> 148229.44
B27: Shares Outstanding | O27: =$E$9 -> 95.91978 | P27: =$E$9 -> 95.91978 | Q27: =$E$9 -> 95.91978
B29: Implied value per share | O29: =O26/O27 -> 1393.8495 | P29: =P26/P27 -> 1797.0971 | Q29: =Q26/Q27 -> 1545.348
B31: Source: The Valuation School, Screener.in
O32: =IF(O29>$D$9,"Undervalued","Overvalued") -> Overvalued | P32: =IF(P29>$D$9,"Undervalued","Overvalued") -> Overvalued | Q32: =IF(Q29>$D$9,"Undervalued","Overvalued") -> Overvalued

Sheet Beta - Comps
B3: S.No. | C3: Name | D3: CMP Rs. | E3: Mar Cap Rs.Cr. | F3: Debt Rs.Cr. | G3: Debt / Eq
B4: 1 | C4: Asian Paints | D4: ='Data Sheet'!B8 -> 2605.6 | E4: ='Data Sheet'!B9 -> 249928.58 | F4: =SUM('Raw FS'!N7:N9) -> 2291 | G4: =F4/E4 -> 0.0091666187
B5: 2 | C5: Berger Paints | D5: 546.25 | E5: 63791.48 | F5: 635.13 | G5: =F5/E5 -> 0.0099563453
B6: 3 | C6: Kansai Nerolac | D6: 215.58 | E6: 17422.14 | F6: 302.73 | G6: =F6/E6 -> 0.017376166
B7: 4 | C7: JSW Dulux | D7: 3205.8 | E7: 14647.68 | F7: 79.1 | G7: =F7/E7 -> 0.0054001726
B8: 5 | C8: Indigo Paints | D8: 1010.05 | E8: 4825.19 | F8: 18.37 | G8: =F8/E8 -> 0.003807104

Sheet Rm
B6: Return on Markets - Nifty 50
B8: Year | C8: Annual
B9: 2011 | C9: -0.2462 | E9: Average Return | G9: =AVERAGE(C9:C23) -> 0.1106
B10: 2012 | C10: 0.277 | E10: Dividend Yield | G10: 0.0139
B11: 2013 | C11: 0.0676 | E11: Total Market Returns | G11: =SUM(G10,G9) -> 0.1245
B12: 2014 | C12: 0.3139
B13: 2015 | C13: -0.0406
B14: 2016 | C14: 0.0301
B15: 2017 | C15: 0.2865
B16: 2018 | C16: 0.0315
B17: 2019 | C17: 0.1202
B18: 2020 | C18: 0.1417
B19: 2021 | C19: 0.2412
B20: 2022 | C20: 0.0432
B21: 2023 | C21: 0.2003
B22: 2024 | C22: 0.0876
B23: 2025 | C23: 0.105

Sheet Analysis
B3: ='Data Sheet'!B1 -> ASIAN PAINTS LTD
B4: =CONCATENATE("(",_xlfn.XLOOKUP(B3,'List Of Stocks'!B2:B5442,'List Of Stocks'!D2:D5442), " | ","BSE Code: ",_xlfn.XLOOKUP(Analysis!B3,'List Of Stocks'!B2:B5442,'List Of Stocks'!C2:C5442,,0)," ) ") -> (ASIANPAINT | BSE Code: 500820 )
B5: =CONCATENATE("INR", " ",'Data Sheet'!B8) -> INR 2605.6
B6: ="52 Week" & " "&"("&"High -" & " INR " &'Football Field Analysis'!Q10 & " " &"LOW - " & " INR " &'Football Field Analysis'!N10 &")" -> 52 Week (High - INR 2985.7 LOW - INR 2115)
B8: About The Company
B9: Asian Paints Ltd is an Indian multinational paint company, headquartered in Mumbai.The company is engaged in the business of manufacturing, selling and distribution of paints, coatings, products related to home décor, bath fittings and providing related services. Asian Paints is India's largest paints company by market share.The company has 27 paint manufacturing facilities in 15 countries, servicing consumers in over 60 countries. Asian Paints is also present in the home improvement and décor space in India
B16: Financial Summary
B67: Return On Equity(ROE)
C68: =HistoricalFS!F3 -> 43555 | D68: =HistoricalFS!G3 -> 43921 | E68: =HistoricalFS!H3 -> 44286 | F68: =HistoricalFS!I3 -> 44651 | G68: =HistoricalFS!J3 -> 45016 | H68: =HistoricalFS!K3 -> 45382 | I68: =HistoricalFS!L3 -> 45747
B69: Net Profit | C69: =IFERROR('Data Sheet'!E30,0) -> 2155.92 | D69: =IFERROR('Data Sheet'!F30,0) -> 2705.17 | E69: =IFERROR('Data Sheet'!G30,0) -> 3139.29 | F69: =IFERROR('Data Sheet'!H30,0) -> 3030.57 | G69: =IFERROR('Data Sheet'!I30,0) -> 4106.45 | H69: =IFERROR('Data Sheet'!J30,0) -> 5460.23 | I69: =IFERROR('Data Sheet'!K30,0) -> 3667.23
B70: Average Shareholder Equity | C70: =IFERROR((('Data Sheet'!E57+'Data Sheet'!E58)+('Data Sheet'!D58+'Data Sheet'!D57))/2,0) -> 8940.39 | D70: =IFERROR((('Data Sheet'!F57+'Data Sheet'!F58)+('Data Sheet'!E58+'Data Sheet'!E57))/2,0) -> 9800.355 | E70: =IFERROR((('Data Sheet'!G57+'Data Sheet'!G58)+('Data Sheet'!F58+'Data Sheet'!F57))/2,0) -> 11468.225 | F70: =IFERROR((('Data Sheet'!H57+'Data Sheet'!H58)+('Data Sheet'!G58+'Data Sheet'!G57))/2,0) -> 13308.925 | G70: =IFERROR((('Data Sheet'!I57+'Data Sheet'!I58)+('Data Sheet'!H58+'Data Sheet'!H57))/2,0) -> 14901.895 | H70: =IFERROR((('Data Sheet'!J57+'Data Sheet'!J58)+('Data Sheet'!I58+'Data Sheet'!I57))/2,0) -> 17360.265 | I70: =IFERROR((('Data Sheet'!K57+'Data Sheet'!K58)+('Data Sheet'!J58+'Data Sheet'!J57))/2,0) -> 19064.055
B71: Return On Equity | C71: =C69/C70 -> 0.24114384 | D71: =D69/D70 -> 0.27602776 | E71: =E69/E70 -> 0.27373809 | F71: =F69/F70 -> 0.2277096 | G71: =G69/G70 -> 0.27556562 | H71: =H69/H70 -> 0.31452458 | I71: =I69/I70 -> 0.19236359
B73: ROE - Dupont Equation
C74: =C68 -> 43555 | D74: =D68 -> 43921 | E74: =E68 -> 44286 | F74: =F68 -> 44651 | G74: =G68 -> 45016 | H74: =H68 -> 45382 | I74: =I68 -> 45747
B75: =B69 -> Net Profit | C75: =C69 -> 2155.92 | D75: =D69 -> 2705.17 | E75: =E69 -> 3139.29 | F75: =F69 -> 3030.57 | G75: =G69 -> 4106.45 | H75: =H69 -> 5460.23 | I75: =I69 -> 3667.23
B76: Revenue | C76: =IFERROR('Data Sheet'!E17,0) -> 19240.13 | D76: =IFERROR('Data Sheet'!F17,0) -> 20211.25 | E76: =IFERROR('Data Sheet'!G17,0) -> 21712.79 | F76: =IFERROR('Data Sheet'!H17,0) -> 29101.28 | G76: =IFERROR('Data Sheet'!I17,0) -> 34488.59 | H76: =IFERROR('Data Sheet'!J17,0) -> 35494.73 | I76: =IFERROR('Data Sheet'!K17,0) -> 33905.62
B77: Net Profit Margin(A) | C77: =C75/C76 -> 0.1120533 | D77: =D75/D76 -> 0.13384476 | E77: =E75/E76 -> 0.14458252 | F77: =F75/F76 -> 0.10413872 | G77: =G75/G76 -> 0.11906691 | H77: =H75/H76 -> 0.15383213 | I77: =I75/I76 -> 0.10815995
C79: =C74 -> 43555 | D79: =D74 -> 43921 | E79: =E74 -> 44286 | F79: =F74 -> 44651 | G79: =G74 -> 45016 | H79: =H74 -> 45382 | I79: =I74 -> 45747
B80: Revenue | C80: =C76 -> 19240.13 | D80: =D76 -> 20211.25 | E80: =E76 -> 21712.79 | F80: =F76 -> 29101.28 | G80: =G76 -> 34488.59 | H80: =H76 -> 35494.73 | I80: =I76 -> 33905.62
B81: Average Total Assets | C81: =IFERROR(('Data Sheet'!E66+'Data Sheet'!D66)/2,0) -> 15006.16 | D81: =IFERROR(('Data Sheet'!F66+'Data Sheet'!E66)/2,0) -> 16193.405 | E81: =IFERROR(('Data Sheet'!G66+'Data Sheet'!F66)/2,0) -> 18246.655 | F81: =IFERROR(('Data Sheet'!H66+'Data Sheet'!G66)/2,0) -> 21656.885 | G81: =IFERROR(('Data Sheet'!I66+'Data Sheet'!H66)/2,0) -> 24368.88 | H81: =IFERROR(('Data Sheet'!J66+'Data Sheet'!I66)/2,0) -> 27840.05 | I81: =IFERROR(('Data Sheet'!K66+'Data Sheet'!J66)/2,0) -> 30128.01
B82: Asset Turnover Ratio(B) | C82: =C80/C81 -> 1.2821488 | D82: =D80/D81 -> 1.2481161 | E82: =E80/E81 -> 1.18996 | F82: =F80/F81 -> 1.3437426 | G82: =G80/G81 -> 1.4152719 | H82: =H80/H81 -> 1.2749521 | I82: =I80/I81 -> 1.1253853
C84: =C79 -> 43555 | D84: =D79 -> 43921 | E84: =E79 -> 44286 | F84: =F79 -> 44651 | G84: =G79 -> 45016 | H84: =H79 -> 45382 | I84: =I79 -> 45747
B85: Average Total Assets | C85: =IFERROR(('Data Sheet'!E66+'Data Sheet'!D66)/2,0) -> 15006.16 | D85: =IFERROR(('Data Sheet'!F66+'Data Sheet'!E66)/2,0) -> 16193.405 | E85: =IFERROR(('Data Sheet'!G66+'Data Sheet'!F66)/2,0) -> 18246.655 | F85: =IFERROR(('Data Sheet'!H66+'Data Sheet'!G66)/2,0) -> 21656.885 | G85: =IFERROR(('Data Sheet'!I66+'Data Sheet'!H66)/2,0) -> 24368.88 | H85: =IFERROR(('Data Sheet'!J66+'Data Sheet'!I66)/2,0) -> 27840.05 | I85: =IFERROR(('Data Sheet'!K66+'Data Sheet'!J66)/2,0) -> 30128.01
B86: Average Shareholder Equity | C86: =IFERROR((('Data Sheet'!E57+'Data Sheet'!E58)+('Data Sheet'!D58+'Data Sheet'!D57))/2,0) -> 8940.39 | D86: =IFERROR((('Data Sheet'!F57+'Data Sheet'!F58)+('Data Sheet'!E58+'Data Sheet'!E57))/2,0) -> 9800.355 | E86: =IFERROR((('Data Sheet'!G57+'Data Sheet'!G58)+('Data Sheet'!F58+'Data Sheet'!F57))/2,0) -> 11468.225 | F86: =IFERROR((('Data Sheet'!H57+'Data Sheet'!H58)+('Data Sheet'!G58+'Data Sheet'!G57))/2,0) -> 13308.925 | G86: =IFERROR((('Data Sheet'!I57+'Data Sheet'!I58)+('Data Sheet'!H58+'Data Sheet'!H57))/2,0) -> 14901.895 | H86: =IFERROR((('Data Sheet'!J57+'Data Sheet'!J58)+('Data Sheet'!I58+'Data Sheet'!I57))/2,0) -> 17360.265 | I86: =IFERROR((('Data Sheet'!K57+'Data Sheet'!K58)+('Data Sheet'!J58+'Data Sheet'!J57))/2,0) -> 19064.055
B87: Financial Leverage(C) | C87: =C85/C86 -> 1.6784682 | D87: =D85/D86 -> 1.6523284 | E87: =E85/E86 -> 1.5910618 | F87: =F85/F86 -> 1.6272453 | G87: =G85/G86 -> 1.6352873 | H87: =H85/H86 -> 1.603665 | I87: =I85/I86 -> 1.5803569
B89: Return On Equity(A*B*C) | C89: =C87*C82*C77 -> 0.24114384 | D89: =D87*D82*D77 -> 0.27602776 | E89: =E87*E82*E77 -> 0.27373809 | F89: =F87*F82*F77 -> 0.2277096 | G89: =G87*G82*G77 -> 0.27556562 | H89: =H87*H82*H77 -> 0.31452458 | I89: =I87*I82*I77 -> 0.19236359
B91: Return On Asset(ROA)
C92: =C84 -> 43555 | D92: =D84 -> 43921 | E92: =E84 -> 44286 | F92: =F84 -> 44651 | G92: =G84 -> 45016 | H92: =H84 -> 45382 | I92: =I84 -> 45747
B93: Net Profit | C93: =C75 -> 2155.92 | D93: =D75 -> 2705.17 | E93: =E75 -> 3139.29 | F93: =F75 -> 3030.57 | G93: =G75 -> 4106.45 | H93: =H75 -> 5460.23 | I93: =I75 -> 3667.23
B94: =B85 -> Average Total Assets | C94: =C85 -> 15006.16 | D94: =D85 -> 16193.405 | E94: =E85 -> 18246.655 | F94: =F85 -> 21656.885 | G94: =G85 -> 24368.88 | H94: =H85 -> 27840.05 | I94: =I85 -> 30128.01
B95: Return On Asset | C95: =C93/C94 -> 0.143669 | D95: =D93/D94 -> 0.16705381 | E95: =E93/E94 -> 0.17204742 | F95: =F93/F94 -> 0.13993564 | G95: =G93/G94 -> 0.16851205 | H95: =H93/H94 -> 0.1961286 | I95: =I93/I94 -> 0.12172161
B97: ROA - Dupont Analysis
C98: =C92 -> 43555 | D98: =D92 -> 43921 | E98: =E92 -> 44286 | F98: =F92 -> 44651 | G98: =G92 -> 45016 | H98: =H92 -> 45382 | I98: =I92 -> 45747
B99: Net Profit | C99: =C93 -> 2155.92 | D99: =D93 -> 2705.17 | E99: =E93 -> 3139.29 | F99: =F93 -> 3030.57 | G99: =G93 -> 4106.45 | H99: =H93 -> 5460.23 | I99: =I93 -> 3667.23
B100: Revenue | C100: =C80 -> 19240.13 | D100: =D80 -> 20211.25 | E100: =E80 -> 21712.79 | F100: =F80 -> 29101.28 | G100: =G80 -> 34488.59 | H100: =H80 -> 35494.73 | I100: =I80 -> 33905.62
B101: Net Profit Margin(A) | C101: =C99/C100 -> 0.1120533 | D101: =D99/D100 -> 0.13384476 | E101: =E99/E100 -> 0.14458252 | F101: =F99/F100 -> 0.10413872 | G101: =G99/G100 -> 0.11906691 | H101: =H99/H100 -> 0.15383213 | I101: =I99/I100 -> 0.10815995
C103: =C98 -> 43555 | D103: =D98 -> 43921 | E103: =E98 -> 44286 | F103: =F98 -> 44651 | G103: =G98 -> 45016 | H103: =H98 -> 45382 | I103: =I98 -> 45747
B104: Revenue | C104: =C100 -> 19240.13 | D104: =D100 -> 20211.25 | E104: =E100 -> 21712.79 | F104: =F100 -> 29101.28 | G104: =G100 -> 34488.59 | H104: =H100 -> 35494.73 | I104: =I100 -> 33905.62
B105: Average Total Assets | C105: =C85 -> 15006.16 | D105: =D85 -> 16193.405 | E105: =E85 -> 18246.655 | F105: =F85 -> 21656.885 | G105: =G85 -> 24368.88 | H105: =H85 -> 27840.05 | I105: =I85 -> 30128.01
B106: Asset Turnover Ratio(B) | C106: =C104/C105 -> 1.2821488 | D106: =D104/D105 -> 1.2481161 | E106: =E104/E105 -> 1.18996 | F106: =F104/F105 -> 1.3437426 | G106: =G104/G105 -> 1.4152719 | H106: =H104/H105 -> 1.2749521 | I106: =I104/I105 -> 1.1253853
...

Sheet HistoricalFS
B2: ="Historical Financial Statement - "&'Data Sheet'!B1 -> Historical Financial Statement - ASIAN PAINTS LTD
B3: Years | C3: ='Data Sheet'!B16 -> 42460 | D3: ='Data Sheet'!C16 -> 42825 | E3: ='Data Sheet'!D16 -> 43190 | F3: ='Data Sheet'!E16 -> 43555 | G3: ='Data Sheet'!F16 -> 43921 | H3: ='Data Sheet'!G16 -> 44286 | I3: ='Data Sheet'!H16 -> 44651 | J3: ='Data Sheet'!I16 -> 45016 | ... L3: ='Data Sheet'!K16 -> 45747 | M3: LTM
A5: # | B5: Income Statement
B6: Sales | C6: =IFERROR('Data Sheet'!B17,0) -> 14271.49 | D6: =IFERROR('Data Sheet'!C17,0) -> 15061.99 | E6: =IFERROR('Data Sheet'!D17,0) -> 16824.55 | F6: =IFERROR('Data Sheet'!E17,0) -> 19240.13 | G6: =IFERROR('Data Sheet'!F17,0) -> 20211.25 | H6: =IFERROR('Data Sheet'!G17,0) -> 21712.79 | I6: =IFERROR('Data Sheet'!H17,0) -> 29101.28 | J6: =IFERROR('Data Sheet'!I17,0) -> 34488.59 | ... L6: =IFERROR('Data Sheet'!K17,0) -> 33905.62 | M6: =IFERROR(SUM('Data Sheet'!H42:K42),0) -> 34695.75
B7: Sales Growth | C7: - | D7: =D6/C6-1 -> 0.055390152 | E7: =E6/D6-1 -> 0.11702039 | F7: =F6/E6-1 -> 0.14357472 | G7: =G6/F6-1 -> 0.050473671 | H7: =H6/G6-1 -> 0.074292288 | I7: =I6/H6-1 -> 0.34028285 | J7: =J6/I6-1 -> 0.18512278 | K7: =K6/J6-1 -> 0.029173127 | ... M7: =M6/L6-1 -> 0.023303806
B9: COGS | C9: =IFERROR(SUM('Data Sheet'!B18,'Data Sheet'!B20:B22)-1*'Data Sheet'!B19,0) -> 9413.84 | D9: =IFERROR(SUM('Data Sheet'!C18,'Data Sheet'!C20:C22)-1*'Data Sheet'!C19,0) -> 9732.66 | E9: =IFERROR(SUM('Data Sheet'!D18,'Data Sheet'!D20:D22)-1*'Data Sheet'!D19,0) -> 11194.17 | F9: =IFERROR(SUM('Data Sheet'!E18,'Data Sheet'!E20:E22)-1*'Data Sheet'!E19,0) -> 12905.81 | G9: =IFERROR(SUM('Data Sheet'!F18,'Data Sheet'!F20:F22)-1*'Data Sheet'!F19,0) -> 13158.02 | H9: =IFERROR(SUM('Data Sheet'!G18,'Data Sheet'!G20:G22)-1*'Data Sheet'!G19,0) -> 14035.07 | I9: =IFERROR(SUM('Data Sheet'!H18,'Data Sheet'!H20:H22)-1*'Data Sheet'!H19,0) -> 20590.57 | J9: =IFERROR(SUM('Data Sheet'!I18,'Data Sheet'!I20:I22)-1*'Data Sheet'!I19,0) -> 23766.7 | ... L9: =IFERROR(SUM('Data Sheet'!K18,'Data Sheet'!K20:K22)-1*'Data Sheet'!K19,0) -> 22741.27 | M9: =IFERROR(SUM('Data Sheet'!H43:K43),0) -> 28350.24
B10: COGS % Sales | C10: =C9/C6 -> 0.65962559 | D10: =D9/D6 -> 0.64617358 | E10: =E9/E6 -> 0.66534736 | F10: =F9/F6 -> 0.67077561 | G10: =G9/G6 -> 0.65102455 | H10: =H9/H6 -> 0.64639643 | I10: =I9/I6 -> 0.7075486 | J10: =J9/J6 -> 0.68911776 | ... M10: =M9/M6 -> 0.81710988
B12: Gross Profit | C12: =C6-C9 -> 4857.65 | D12: =D6-D9 -> 5329.33 | E12: =E6-E9 -> 5630.38 | F12: =F6-F9 -> 6334.32 | G12: =G6-G9 -> 7053.23 | H12: =H6-H9 -> 7677.72 | I12: =I6-I9 -> 8510.71 | J12: =J6-J9 -> 10721.89 | ... M12: =M6-M9 -> 6345.51
B13: Gross Margins | C13: =C12/C6 -> 0.34037441 | D13: =D12/D6 -> 0.35382642 | E13: =E12/E6 -> 0.33465264 | F13: =F12/F6 -> 0.32922439 | G13: =G12/G6 -> 0.34897545 | H13: =H12/H6 -> 0.35360357 | I13: =I12/I6 -> 0.2924514 | J13: =J12/J6 -> 0.31088224 | ... M13: =M12/M6 -> 0.18289012
B15: Selling & General Expenses | C15: =IFERROR(SUM('Data Sheet'!B23:B24),0) -> 2132.61 | D15: =IFERROR(SUM('Data Sheet'!C23:C24),0) -> 2335.57 | E15: =IFERROR(SUM('Data Sheet'!D23:D24),0) -> 2426.37 | F15: =IFERROR(SUM('Data Sheet'!E23:E24),0) -> 2569.38 | G15: =IFERROR(SUM('Data Sheet'!F23:F24),0) -> 2891.46 | H15: =IFERROR(SUM('Data Sheet'!G23:G24),0) -> 2822.12 | I15: =IFERROR(SUM('Data Sheet'!H23:H24),0) -> 3707.1 | J15: =IFERROR(SUM('Data Sheet'!I23:I24),0) -> 4462.05 | ... L15: =IFERROR(SUM('Data Sheet'!K23:K24),0) -> 5158.14
B16: S&G Exp % Sales | C16: =C15/C6 -> 0.14943149 | D16: =D15/D6 -> 0.15506384 | E16: =E15/E6 -> 0.14421604 | F16: =F15/F6 -> 0.13354276 | G16: =G15/G6 -> 0.14306191 | H16: =H15/H6 -> 0.12997501 | I16: =I15/I6 -> 0.12738615 | J16: =J15/J6 -> 0.12937757 | ... M16: =M15/M6 -> 0
B18: EBITDA | C18: =C12-C15 -> 2725.04 | D18: =D12-D15 -> 2993.76 | E18: =E12-E15 -> 3204.01 | F18: =F12-F15 -> 3764.94 | G18: =G12-G15 -> 4161.77 | H18: =H12-H15 -> 4855.6 | I18: =I12-I15 -> 4803.61 | J18: =J12-J15 -> 6259.84 | ... L18: =L12-L15 -> 6006.21 | M18: =IFERROR(SUM('Data Sheet'!H51:K51),0) -> 6755.97
B19: EBITDA Margins | C19: =C18/C6 -> 0.19094292 | D19: =D18/D6 -> 0.19876258 | E19: =E18/E6 -> 0.19043659 | F19: =F18/F6 -> 0.19568163 | G19: =G18/G6 -> 0.20591354 | H19: =H18/H6 -> 0.22362856 | I19: =I18/I6 -> 0.16506525 | J19: =J18/J6 -> 0.18150467 | ... M19: =M18/M6 -> 0.19472039
B21: Interest | C21: =IFERROR('Data Sheet'!B27,0) -> 49 | D21: =IFERROR('Data Sheet'!C27,0) -> 37.33 | E21: =IFERROR('Data Sheet'!D27,0) -> 41.47 | F21: =IFERROR('Data Sheet'!E27,0) -> 110.47 | G21: =IFERROR('Data Sheet'!F27,0) -> 102.33 | H21: =IFERROR('Data Sheet'!G27,0) -> 91.63 | I21: =IFERROR('Data Sheet'!H27,0) -> 95.41 | J21: =IFERROR('Data Sheet'!I27,0) -> 144.45 | ... L21: =IFERROR('Data Sheet'!K27,0) -> 227.02 | M21: =IFERROR(SUM('Data Sheet'!H46:K46),0) -> 189.1
B22: Interest % Sales | C22: =C21/C6 -> 0.0034334187 | D22: =D21/D6 -> 0.0024784242 | E22: =E21/E6 -> 0.0024648505 | F22: =F21/F6 -> 0.0057416452 | G22: =G21/G6 -> 0.0050630218 | H22: =H21/H6 -> 0.0042200933 | I22: =I21/I6 -> 0.0032785499 | J22: =J21/J6 -> 0.0041883417 | ... M22: =M21/M6 -> 0.0054502353
B24: Depreciation | C24: =IFERROR('Data Sheet'!B26,0) -> 275.58 | D24: =IFERROR('Data Sheet'!C26,0) -> 334.79 | E24: =IFERROR('Data Sheet'!D26,0) -> 360.47 | F24: =IFERROR('Data Sheet'!E26,0) -> 622.14 | G24: =IFERROR('Data Sheet'!F26,0) -> 780.5 | H24: =IFERROR('Data Sheet'!G26,0) -> 791.27 | I24: =IFERROR('Data Sheet'!H26,0) -> 816.36 | J24: =IFERROR('Data Sheet'!I26,0) -> 858.02 | ... L24: =IFERROR('Data Sheet'!K26,0) -> 1026.34 | M24: =IFERROR(SUM('Data Sheet'!H45:K45),0) -> 1219.97
B25: Depreciation%Sales | C25: =C24/C6 -> 0.019309827 | D25: =D24/D6 -> 0.022227475 | E25: =E24/E6 -> 0.021425239 | F25: =F24/F6 -> 0.03233554 | G25: =G24/G6 -> 0.038617107 | H25: =H24/H6 -> 0.036442576 | I25: =I24/I6 -> 0.028052374 | J25: =J24/J6 -> 0.024878373 | ... M25: =M24/M6 -> 0.035161943
B27: Earnings Before Tax | C27: =IFERROR(C18-SUM(C24,C21),0) -> 2400.46 | D27: =IFERROR(D18-SUM(D24,D21),0) -> 2621.64 | E27: =IFERROR(E18-SUM(E24,E21),0) -> 2802.07 | F27: =IFERROR(F18-SUM(F24,F21),0) -> 3032.33 | G27: =IFERROR(G18-SUM(G24,G21),0) -> 3278.94 | H27: =IFERROR(H18-SUM(H24,H21),0) -> 3972.7 | I27: =IFERROR(I18-SUM(I24,I21),0) -> 3891.84 | J27: =IFERROR(J18-SUM(J24,J21),0) -> 5257.37 | ... M27: =IFERROR(M18-SUM(M24,M21),0) -> 5346.9
B28: EBT % Sales | C28: =C27/C6 -> 0.16819968 | D28: =D27/D6 -> 0.17405668 | E28: =E27/E6 -> 0.1665465 | F28: =F27/F6 -> 0.15760444 | G28: =G27/G6 -> 0.16223341 | H28: =H27/H6 -> 0.18296589 | I28: =I27/I6 -> 0.13373432 | J28: =J27/J6 -> 0.15243795 | ... M28: =M27/M6 -> 0.15410821
B30: Tax | C30: =IFERROR('Data Sheet'!B29,0) -> 844.49 | D30: =IFERROR('Data Sheet'!C29,0) -> 943.29 | E30: =IFERROR('Data Sheet'!D29,0) -> 1040.96 | F30: =IFERROR('Data Sheet'!E29,0) -> 1098.06 | G30: =IFERROR('Data Sheet'!F29,0) -> 854.85 | H30: =IFERROR('Data Sheet'!G29,0) -> 1097.6 | I30: =IFERROR('Data Sheet'!H29,0) -> 1102.91 | J30: =IFERROR('Data Sheet'!I29,0) -> 1493.5 | ... L30: =IFERROR('Data Sheet'!K29,0) -> 1393.36 | M30: =IFERROR(SUM('Data Sheet'!H48:K48),0) -> 1501.54
B31: Effective Tax Rate | C31: =C30/C27 -> 0.3518034 | D31: =D30/D27 -> 0.35980913 | E31: =E30/E27 -> 0.37149679 | F31: =F30/F27 -> 0.36211758 | G31: =G30/G27 -> 0.26070925 | H31: =H30/H27 -> 0.27628565 | I31: =I30/I27 -> 0.28339038 | J31: =J30/J27 -> 0.2840774 | ... M31: =M30/M27 -> 0.2808244
B33: Net Profit | C33: =IFERROR(C27-C30,0) -> 1555.97 | D33: =IFERROR(D27-D30,0) -> 1678.35 | E33: =IFERROR(E27-E30,0) -> 1761.11 | F33: =IFERROR(F27-F30,0) -> 1934.27 | G33: =IFERROR(G27-G30,0) -> 2424.09 | H33: =IFERROR(H27-H30,0) -> 2875.1 | I33: =IFERROR(I27-I30,0) -> 2788.93 | J33: =IFERROR(J27-J30,0) -> 3763.87 | ... M33: =IFERROR(M27-M30,0) -> 3845.36
B34: Net Margins | C34: =C33/C6 -> 0.10902646 | D34: =D33/D6 -> 0.1114295 | E34: =E33/E6 -> 0.10467501 | F34: =F33/F6 -> 0.1005331 | G34: =G33/G6 -> 0.11993766 | H34: =H33/H6 -> 0.13241504 | I34: =I33/I6 -> 0.095835303 | J34: =J33/J6 -> 0.10913377 | ... M34: =M33/M6 -> 0.11083087
B36: No of Equity Shares | C36: =IFERROR('Data Sheet'!B93,0) -> 95.92 | D36: =IFERROR('Data Sheet'!C93,0) -> 95.92 | E36: =IFERROR('Data Sheet'!D93,0) -> 95.92 | F36: =IFERROR('Data Sheet'!E93,0) -> 95.92 | G36: =IFERROR('Data Sheet'!F93,0) -> 95.92 | H36: =IFERROR('Data Sheet'!G93,0) -> 95.92 | I36: =IFERROR('Data Sheet'!H93,0) -> 95.92 | J36: =IFERROR('Data Sheet'!I93,0) -> 95.92 | ... L36: =IFERROR('Data Sheet'!K93,0) -> 95.92 | M36: =L36 -> 95.92
B38: Earnings per Share | C38: =IFERROR(C33/C36,0) -> 16.221539 | D38: =IFERROR(D33/D36,0) -> 17.497394 | E38: =IFERROR(E33/E36,0) -> 18.360196 | F38: =IFERROR(F33/F36,0) -> 20.16545 | G38: =IFERROR(G33/G36,0) -> 25.271997 | H38: =IFERROR(H33/H36,0) -> 29.973937 | I38: =IFERROR(I33/I36,0) -> 29.075584 | J38: =IFERROR(J33/J36,0) -> 39.239679 | ... M38: =IFERROR(M33/M36,0) -> 40.089241
B39: EPS Growth % | D39: =IFERROR(D38/C38-1,0) -> 0.078651902 | E39: =IFERROR(E38/D38-1,0) -> 0.049310335 | F39: =IFERROR(F38/E38-1,0) -> 0.098324352 | G39: =IFERROR(G38/F38-1,0) -> 0.25323249 | H39: =IFERROR(H38/G38-1,0) -> 0.18605332 | I39: =IFERROR(I38/H38-1,0) -> -0.029971131 | J39: =IFERROR(J38/I38-1,0) -> 0.34957493 | K39: =IFERROR(K38/J38-1,0) -> 0.25847333 | ... M39: =IFERROR(M38/L38-1,0) -> 0.14462612
B41: Dividend per Share | C41: =IFERROR('Data Sheet'!B31/HistoricalFS!C36,0) -> 7.5 | D41: =IFERROR('Data Sheet'!C31/HistoricalFS!D36,0) -> 10.300042 | E41: =IFERROR('Data Sheet'!D31/HistoricalFS!E36,0) -> 8.6999583 | F41: =IFERROR('Data Sheet'!E31/HistoricalFS!F36,0) -> 10.5 | G41: =IFERROR('Data Sheet'!F31/HistoricalFS!G36,0) -> 12 | H41: =IFERROR('Data Sheet'!G31/HistoricalFS!H36,0) -> 17.849979 | I41: =IFERROR('Data Sheet'!H31/HistoricalFS!I36,0) -> 19.150021 | J41: =IFERROR('Data Sheet'!I31/HistoricalFS!J36,0) -> 25.650021 | ... M41: =IFERROR('Data Sheet'!L31/HistoricalFS!M36,0) -> 0
B42: Dividend payout ratio | C42: =IFERROR(C41/C38,0) -> 0.46234825 | D42: =IFERROR(D41/D38,0) -> 0.58866148 | E42: =IFERROR(E41/E38,0) -> 0.47384888 | F42: =IFERROR(F41/F38,0) -> 0.52069256 | G42: =IFERROR(G41/G38,0) -> 0.47483386 | H42: =IFERROR(H41/H38,0) -> 0.59551668 | I42: =IFERROR(I41/I38,0) -> 0.65862894 | J42: =IFERROR(J41/J38,0) -> 0.65367561 | ... M42: =IFERROR(M41/M38,0) -> 0
B44: Retained Earnings | C44: =IFERROR(IF(C38>C41,1-C42,0),0) -> 0.53765175 | D44: =IFERROR(IF(D38>D41,1-D42,0),0) -> 0.41133852 | E44: =IFERROR(IF(E38>E41,1-E42,0),0) -> 0.52615112 | F44: =IFERROR(IF(F38>F41,1-F42,0),0) -> 0.47930744 | G44: =IFERROR(IF(G38>G41,1-G42,0),0) -> 0.52516614 | H44: =IFERROR(IF(H38>H41,1-H42,0),0) -> 0.40448332 | I44: =IFERROR(IF(I38>I41,1-I42,0),0) -> 0.34137106 | J44: =IFERROR(IF(J38>J41,1-J42,0),0) -> 0.34632439 | ... M44: =IFERROR(IF(M38>M41,1-M42,0),0) -> 1
A46: # | B46: Balance Sheet
B47: Equity Share Capital | C47: =IFERROR('Data Sheet'!B57,0) -> 95.92 | D47: =IFERROR('Data Sheet'!C57,0) -> 95.92 | E47: =IFERROR('Data Sheet'!D57,0) -> 95.92 | F47: =IFERROR('Data Sheet'!E57,0) -> 95.92 | G47: =IFERROR('Data Sheet'!F57,0) -> 95.92 | H47: =IFERROR('Data Sheet'!G57,0) -> 95.92 | I47: =IFERROR('Data Sheet'!H57,0) -> 95.92 | J47: =IFERROR('Data Sheet'!I57,0) -> 95.92 | ... L47: =IFERROR('Data Sheet'!K57,0) -> 95.92
B48: Reserves | C48: =IFERROR('Data Sheet'!B58,0) -> 6428.9 | D48: =IFERROR('Data Sheet'!C58,0) -> 7507.97 | E48: =IFERROR('Data Sheet'!D58,0) -> 8314.31 | F48: =IFERROR('Data Sheet'!E58,0) -> 9374.63 | G48: =IFERROR('Data Sheet'!F58,0) -> 10034.24 | H48: =IFERROR('Data Sheet'!G58,0) -> 12710.37 | I48: =IFERROR('Data Sheet'!H58,0) -> 13715.64 | J48: =IFERROR('Data Sheet'!I58,0) -> 15896.31 | ... L48: =IFERROR('Data Sheet'!K58,0) -> 19303.89
B49: Borrowings | C49: =IFERROR('Data Sheet'!B59,0) -> 323.29 | D49: =IFERROR('Data Sheet'!C59,0) -> 560.34 | E49: =IFERROR('Data Sheet'!D59,0) -> 533.43 | F49: =IFERROR('Data Sheet'!E59,0) -> 1319.6 | G49: =IFERROR('Data Sheet'!F59,0) -> 1118.5 | H49: =IFERROR('Data Sheet'!G59,0) -> 1093.12 | I49: =IFERROR('Data Sheet'!H59,0) -> 1586.88 | J49: =IFERROR('Data Sheet'!I59,0) -> 1932.62 | ... L49: =IFERROR('Data Sheet'!K59,0) -> 2290.29
B50: Other Liabilities | C50: =IFERROR('Data Sheet'!B60,0) -> 3710.92 | D50: =IFERROR('Data Sheet'!C60,0) -> 4240.96 | E50: =IFERROR('Data Sheet'!D60,0) -> 4819.82 | F50: =IFERROR('Data Sheet'!E60,0) -> 5458.69 | G50: =IFERROR('Data Sheet'!F60,0) -> 4889.31 | H50: =IFERROR('Data Sheet'!G60,0) -> 6455.93 | I50: =IFERROR('Data Sheet'!H60,0) -> 7559.99 | J50: =IFERROR('Data Sheet'!I60,0) -> 7854.48 | ... L50: =IFERROR('Data Sheet'!K60,0) -> 8665.15
B51: Total Liabilities | C51: =IFERROR('Data Sheet'!B61,0) -> 10559.03 | D51: =IFERROR('Data Sheet'!C61,0) -> 12405.19 | E51: =IFERROR('Data Sheet'!D61,0) -> 13763.48 | F51: =IFERROR('Data Sheet'!E61,0) -> 16248.84 | G51: =IFERROR('Data Sheet'!F61,0) -> 16137.97 | H51: =IFERROR('Data Sheet'!G61,0) -> 20355.34 | I51: =IFERROR('Data Sheet'!H61,0) -> 22958.43 | J51: =IFERROR('Data Sheet'!I61,0) -> 25779.33 | ... L51: =IFERROR('Data Sheet'!K61,0) -> 30355.25
B53: Fixed Assets Net Block | C53: =IFERROR('Data Sheet'!B62,0) -> 3416.35 | D53: =IFERROR('Data Sheet'!C62,0) -> 3303.74 | E53: =IFERROR('Data Sheet'!D62,0) -> 3732.24 | F53: =IFERROR('Data Sheet'!E62,0) -> 6496.56 | G53: =IFERROR('Data Sheet'!F62,0) -> 6272.31 | H53: =IFERROR('Data Sheet'!G62,0) -> 5858.52 | I53: =IFERROR('Data Sheet'!H62,0) -> 5519.06 | J53: =IFERROR('Data Sheet'!I62,0) -> 5770.46 | ... L53: =IFERROR('Data Sheet'!K62,0) -> 9220.1
B54: Capital Work in Progress | C54: =IFERROR('Data Sheet'!B63,0) -> 106.59 | D54: =IFERROR('Data Sheet'!C63,0) -> 257.54 | E54: =IFERROR('Data Sheet'!D63,0) -> 1405.11 | F54: =IFERROR('Data Sheet'!E63,0) -> 209.67 | G54: =IFERROR('Data Sheet'!F63,0) -> 140.24 | H54: =IFERROR('Data Sheet'!G63,0) -> 182.98 | I54: =IFERROR('Data Sheet'!H63,0) -> 426.43 | J54: =IFERROR('Data Sheet'!I63,0) -> 1019.59 | ... L54: =IFERROR('Data Sheet'!K63,0) -> 1254.49
